<?xml version="1.0" encoding="utf-8"?>
<robot xmlns:xacro="http://ros.org/wiki/xacro" name="shanti_description">

  <!-- Define reusable materials -->
  <material name="camera_aluminum">
    <color rgba="0.5 0.5 0.5 1"/>
  </material>

  <!-- Base Link Macro -->
  <xacro:macro name="base_link_macro" params="">
    <link name="base_link">
      <inertial>
        <origin xyz="-0.091898 -0.0027325 -0.011239" rpy="0 0 0" />
        <mass value="72.574" />
        <inertia ixx="4.6083" ixy="-0.019972" ixz="1.7223" iyy="8.7822" iyz="-0.0020742" izz="7.6168" />
      </inertial>
      <visual>
        <origin xyz="0 0 0" rpy="0 0 0" />
        <geometry>
          <mesh filename="package://shanti_description/meshes/base_link.STL" />
        </geometry>
        <material name="">
          <color rgba="0.89804 0.91765 0.92941 1" />
        </material>
      </visual>
      <collision>
        <origin xyz="0 0 0" rpy="0 0 0" />
        <geometry>
          <mesh filename="package://shanti_description/meshes/base_link.STL" />
        </geometry>
      </collision>
    </link>
    <gazebo reference="base_link">
      <mu1 value="0.1" />
      <mu2 value="0.1" />
      <kp value="10000000.0" />
      <kd value="1.0" />
      <fdir1 value="1 0 0" />
      <turnGravityOff>false</turnGravityOff>
    </gazebo>
  </xacro:macro>

  <!-- Right Wheel Link Macro -->
  <xacro:macro name="right_wheel_link_macro" params="">
    <link name="right_wheel_link">
      <inertial>
        <origin xyz="4.0552E-06 0.00062225 9.8151E-06" rpy="0 0 0" />
        <mass value="2.8396" />
        <inertia ixx="0.0090728" ixy="5.1326E-07" ixz="7.1343E-07" iyy="0.014189" iyz="1.2423E-06" izz="0.0090742" />
      </inertial>
      <visual>
        <origin xyz="0 0 0" rpy="0 0 0" />
        <geometry>
          <mesh filename="package://shanti_description/meshes/right_wheel_link.STL" />
        </geometry>
        <material name="">
          <color rgba="0.79216 0.81961 0.93333 1" />
        </material>
      </visual>
      <collision>
        <origin xyz="0 0 0" rpy="0 0 0" />
        <geometry>
          <mesh filename="package://shanti_description/meshes/right_wheel_link.STL" />
        </geometry>
      </collision>
    </link>
    <gazebo reference="right_wheel_link">
      <mu1 value="10000000.0" />
      <mu2 value="10000000.0" />
      <kp value="10000000.0" />
      <kd value="1.0" />
      <fdir1 value="1 0 0" />
      <material>Gazebo/Grey</material>
      <turnGravityOff>false</turnGravityOff>
    </gazebo>
    <joint name="right_wheel_joint" type="continuous">
      <origin xyz="0.28904 -0.32118 -0.15799" rpy="0 0 0" />
      <parent link="base_link" />
      <child link="right_wheel_link" />
      <axis xyz="0 1 0" />
      <dynamics friction="0" />
    </joint>
  </xacro:macro>

  <!-- Left Wheel Link Macro -->
  <xacro:macro name="left_wheel_link_macro" params="">
    <link name="left_wheel_link">
      <inertial>
        <origin xyz="-1.062E-05 -0.00062225 -2.7756E-17" rpy="0 0 0" />
        <mass value="2.8396" />
        <inertia ixx="0.0090745" ixy="1.3441E-06" ixz="-7.8936E-21" iyy="0.014189" iyz="3.8874E-21" izz="0.0090725" />
      </inertial>
      <visual>
        <origin xyz="0 0 0" rpy="0 0 0" />
        <geometry>
          <mesh filename="package://shanti_description/meshes/left_wheel_link.STL" />
        </geometry>
        <material name="">
          <color rgba="0.79216 0.81961 0.93333 1" />
        </material>
      </visual>
      <collision>
        <origin xyz="0 0 0" rpy="0 0 0" />
        <geometry>
          <mesh filename="package://shanti_description/meshes/left_wheel_link.STL" />
        </geometry>
      </collision>
    </link>
    <gazebo reference="left_wheel_link">
      <mu1 value="10000000.0" />
      <mu2 value="10000000.0" />
      <kp value="10000000.0" />
      <kd value="1.0" />
      <fdir1 value="1 0 0" />
      <material>Gazebo/Grey</material>
      <turnGravityOff>false</turnGravityOff>
    </gazebo>
    <joint name="left_wheel_joint" type="continuous">
      <origin xyz="0.28904 0.32118 -0.15799" rpy="0 0 0" />
      <parent link="base_link" />
      <child link="left_wheel_link" />
      <axis xyz="0 1 0" />
      <dynamics friction="0" />
    </joint>
  </xacro:macro>

  <!-- Camera Macro -->
  <xacro:macro name="camera_macro" params="">
    <link name="camera_link">
      <visual>
        <origin rpy="1.57079632679 0 1.57079632679" xyz="0.0149 -0.0175 0" />
        <geometry>
          <mesh filename="package://realsense2_description/meshes/d435.dae" />
        </geometry>
        <material name="camera_aluminum" />
      </visual>
      <collision>
        <origin rpy="0 0 0" xyz="0 -0.0175 0" />
        <geometry>
          <box size="0.02505 0.09 0.025" />
        </geometry>
      </collision>
      <inertial>
        <mass value="0.564"/>
        <origin xyz="0 0 0"/>
        <inertia ixx="0.003881243" ixy="0.0" ixz="0.0" iyy="0.000498940" iyz="0.0" izz="0.003879257"/>
      </inertial>
    </link>
    <joint name="camera_base_mount_joint" type="fixed">
      <origin rpy="0 0 0" xyz="0.0149 -0.0175 0"/>
      <parent link="base_link"/>
      <child link="camera_link"/>
    </joint>
    <gazebo reference="camera_link">
      <self_collide>0</self_collide>
      <enable_wind>0</enable_wind>
      <kinematic>0</kinematic>
      <gravity>1</gravity>
      <sensor name="cameracolor" type="camera">
        <camera name="camera">
          <horizontal_fov>1.21125850088</horizontal_fov>
          <image>
            <width>640</width>
            <height>480</height>
            <format>RGB_INT8</format>
          </image>
          <clip>
            <near>0.1</near>
            <far>100</far>
          </clip>
          <noise>
            <type>gaussian</type>
            <mean>0.0</mean>
            <stddev>0.007</stddev>
          </noise>
        </camera>
        <always_on>1</always_on>
        <update_rate>30</update_rate>
        <visualize>0</visualize>
      </sensor>
    </gazebo>
  </xacro:macro>

  <!-- Velodyne Lidar Macro -->
  <xacro:macro name="velodyne_lidar_macro" params="">
    <link name="velodyne_base_link">
      <inertial>
        <mass value="0.83"/>
        <origin xyz="0 0 0.03585"/>
        <inertia ixx="0.00090805942" ixy="0" ixz="0" iyy="0.00090805942" iyz="0" izz="0.0011049624"/>
      </inertial>
      <visual>
        <geometry>
          <mesh filename="package://velodyne_description/meshes/VLP16_base_1.dae" />
        </geometry>
      </visual>
      <collision>
        <origin xyz="0 0 0.03585"/>
        <geometry>
          <cylinder radius="0.0516" length="0.0717"/>
        </geometry>
      </collision>
    </link>
    <link name="velodyne">
      <inertial>
        <mass value="0.01"/>
        <origin xyz="0 0 0"/>
        <inertia ixx="1e-7" ixy="0" ixz="0" iyy="1e-7" iyz="0" izz="1e-7"/>
      </inertial>
      <visual>
        <origin xyz="0 0 -0.0377" />
        <geometry>
          <mesh filename="package://velodyne_description/meshes/VLP16_scan.dae" />
        </geometry>
      </visual>
    </link>
    <joint name="velodyne_base_mount_joint" type="fixed">
      <origin rpy="0 0 0" xyz="0.46 0 0.48"/>
      <parent link="base_link"/>
      <child link="velodyne_base_link"/>
    </joint>
    <joint name="velodyne_base_scan_joint" type="fixed">
      <origin xyz="0 0 0.0377" rpy="0 0 0" />
      <parent link="velodyne_base_link" />
      <child link="velodyne"/>
    </joint>
    <gazebo reference="velodyne">
      <sensor type="ray" name="velodyne-VLP16">
        <pose>0 0 0 0 0 0</pose>
        <visualize>false</visualize>
        <update_rate>10</update_rate>
        <ray>
          <scan>
            <horizontal>
              <samples>1875</samples>
              <resolution>1</resolution>
              <min_angle>-3.141592</min_angle>
              <max_angle>3.141592</max_angle>
            </horizontal>
            <vertical>
              <samples>16</samples>
              <resolution>1</resolution>
              <min_angle>-0.261799</min_angle>
              <max_angle>0.261799</max_angle>
            </vertical>
          </scan>
          <range>
            <min>0.3</min>
            <max>131.0</max>
            <resolution>0.001</resolution>
          </range>
          <noise>
            <type>gaussian</type>
            <mean>0.0</mean>
            <stddev>0.0</stddev>
          </noise>
        </ray>
        <plugin name="gazebo_ros_laser_controller" filename="libgazebo_ros_velodyne_laser.so">
          <topicName>/scan</topicName>
          <frameName>velodyne</frameName>
          <min_range>0.9</min_range>
          <max_range>130.0</max_range>
          <gaussianNoise>0.008</gaussianNoise>
        </plugin>
      </sensor>
    </gazebo>
  </xacro:macro>

  <!-- Instantiate all components -->
  <xacro:base_link_macro />
  <xacro:right_wheel_link_macro />
  <xacro:left_wheel_link_macro />
  <xacro:camera_macro />
  <xacro:velodyne_lidar_macro />

</robot>

